Traceback (most recent call last):
  File "/vol/miltank/projects/practical_sose25/atlas_based_registeration/utils/crop_knee_patella.py", line 18, in <module>
    arr = seg.get_array()
          ^^^^^^^^^^^^^^^
  File "/vol/miltank/projects/practical_sose25/atlas_based_registeration/TPTBox/TPTBox/core/nii_wrapper.py", line 486, in get_array
    return self.get_seg_array()
           ^^^^^^^^^^^^^^^^^^^^
  File "/vol/miltank/projects/practical_sose25/atlas_based_registeration/TPTBox/TPTBox/core/nii_wrapper.py", line 482, in get_seg_array
    self._unpack()
  File "/vol/miltank/projects/practical_sose25/atlas_based_registeration/TPTBox/TPTBox/core/nii_wrapper.py", line 317, in _unpack
    raise EOFError(f"{self.nii.get_filename()}: {e!s}\nThe file is probably brocken beyond repair, due killing a software during nifty saving.") from None
EOFError: /vol/miltank/projects/practical_sose25/atlas_based_registeration/data/dataset-myelom/derivatives/CTFU00931/ses-20100420/sub-CTFU00931_ses-20100420_sequ-4_seg-bone_msk.nii.gz: Expected 720312500 bytes, got 476953125 bytes from 
 - could the file be damaged?
The file is probably brocken beyond repair, due killing a software during nifty saving.

ERROR conda.cli.main_run:execute(125): `conda run python /vol/miltank/projects/practical_sose25/atlas_based_registeration/utils/crop_knee_patella.py` failed. (See above for error)
